Workbook

Sheet Sheet2
A3: Region | B3: Average of Profit
A4: East | B4: 12493.09
A5: North | B5: 16728.373
A6: South | B6: 19174.39
A7: West | B7: 11221.251
A8: Grand Total | B8: 14483.475

Sheet Dashboard
A1: =SUM(Sheet1!Q2:Q351) -> 22459473
A2: =AVERAGE(Sheet1!R2:R351) -> 14483.475
A3: {=_xlfn.UNIQUE(Sheet1!B2:B351)} -> East
A4: West
A5: North
A6: South
A8: =SUMIFS(Sheet1!Q:Q,Sheet1!B:B,D4) -> 0
A10: {=_xlfn.UNIQUE(Sheet1!D2:D351)} -> Beverages
A11: Food
A12: Clothing
A13: Furniture
A14: Electronics
A16: =SUMIFS(Sheet1!Q:Q,Sheet1!D:D,H4) -> 0

Sheet Sheet3
A3: Sum of Total Revenue | B3: Region
A4: Category | B4: East | C4: North | D4: South | E4: West | F4: Grand Total
A5: Beverages | B5: 1110756.7 | C5: 1276139.2 | D5: 1199637.7 | E5: 1977673.9 | F5: 5564207.6
A6: Clothing | B6: 1587286.2 | C6: 629674.49 | D6: 496502.89 | E6: 1133988.9 | F6: 3847452.6
A7: Electronics | B7: 946379.14 | C7: 950484.27 | D7: 1068292.4 | E7: 1557975.8 | F7: 4523131.6
A8: Food | B8: 886856.06 | C8: 1658446.5 | D8: 695848.67 | E8: 823912.56 | F8: 4065063.8
A9: Furniture | B9: 1764250.3 | C9: 731274.15 | D9: 832820.25 | E9: 1131273.3 | F9: 4459617.9
A10: Grand Total | B10: 6295528.4 | C10: 5246018.7 | D10: 4293101.9 | E10: 6624824.5 | F10: 22459473

Sheet Sheet1
A1: Order ID | B1: Region | C1: Country | D1: Category | E1: Sales Channel | F1: Order Priority | G1: Order Date | H1: Units Sold | I1: Unit Price | J1: Unit Cost | K1: Region Count | L1: Category Count | M1: Region Filled | N1: Category Filled | O1: Units Sold Filled | P1: Unit Price Filled | Q1: Total Revenue | R1: Profit
A2: ORD0001 | B2: East | C2: Germany | D2: Beverages | E2: Online | F2: High | G2: 44927 | H2: 235 | I2: 152.92 | J2: 153.6 | K2: =IF(B2="",0,COUNTIF($B$2:$B$351,B2)) -> 91 | L2: =IF(D2="",0,COUNTIF($D$2:$D$351,D2)) -> 83 | M2: =IF(B2="",$Z$18,B2) -> East | N2: =IF(D2="",$Z$19,D2) -> Beverages | O2: =IF(H2="",$Y$24,H2) -> 235 | P2: =IF(I2="",$Z$24,I2) -> 152.92 | Q2: =H2*I2 -> 35936.2 | R2: =Q2-(H2*J2) -> -159.8
A3: ORD0002 | B3: West | C3: India | D3: Food | E3: Online | F3: Low | G3: 44928 | H3: 341 | I3: 467.92 | J3: 139.84 | K3: =IF(B3="",0,COUNTIF($B$2:$B$351,B3)) -> 106 | L3: =IF(D3="",0,COUNTIF($D$2:$D$351,D3)) -> 61 | M3: =IF(B3="",$Z$18,B3) -> West | N3: =IF(D3="",$Z$19,D3) -> Food | O3: =IF(H3="",$Y$24,H3) -> 341 | P3: =IF(I3="",$Z$24,I3) -> 467.92 | Q3: =H3*I3 -> 159560.72 | R3: =Q3-(H3*J3) -> 111875.28
A4: ORD0003 | B4: North | C4: India | D4: Clothing | E4: Offline | F4: High | G4: 44929 | H4: 179 | I4: 473.94 | J4: 97.14 | K4: =IF(B4="",0,COUNTIF($B$2:$B$351,B4)) -> 78 | L4: =IF(D4="",0,COUNTIF($D$2:$D$351,D4)) -> 67 | M4: =IF(B4="",$Z$18,B4) -> North | N4: =IF(D4="",$Z$19,D4) -> Clothing | O4: =IF(H4="",$Y$24,H4) -> 179 | P4: =IF(I4="",$Z$24,I4) -> 473.94 | Q4: =H4*I4 -> 84835.26 | R4: =Q4-(H4*J4) -> 67447.2
A5: ORD0004 | B5: East | C5: USA | D5: Furniture | E5: Offline | F5: Medium | G5: 44930 | H5: 18 | I5: 314.53 | J5: 204.87 | K5: =IF(B5="",0,COUNTIF($B$2:$B$351,B5)) -> 91 | L5: =IF(D5="",0,COUNTIF($D$2:$D$351,D5)) -> 69 | M5: =IF(B5="",$Z$18,B5) -> East | N5: =IF(D5="",$Z$19,D5) -> Furniture | O5: =IF(H5="",$Y$24,H5) -> 18 | P5: =IF(I5="",$Z$24,I5) -> 314.53 | Q5: =H5*I5 -> 5661.54 | R5: =Q5-(H5*J5) -> 1973.88
A6: ORD0005 | B6: East | C6: India | D6: Furniture | E6: Offline | F6: Medium | G6: 44931 | H6: 472 | I6: 392.79 | J6: 330.46 | K6: =IF(B6="",0,COUNTIF($B$2:$B$351,B6)) -> 91 | L6: =IF(D6="",0,COUNTIF($D$2:$D$351,D6)) -> 69 | M6: =IF(B6="",$Z$18,B6) -> East | N6: =IF(D6="",$Z$19,D6) -> Furniture | O6: =IF(H6="",$Y$24,H6) -> 472 | P6: =IF(I6="",$Z$24,I6) -> 392.79 | Q6: =H6*I6 -> 185396.88 | R6: =Q6-(H6*J6) -> 29419.76 | Y6: Column | Z6: Missing values
A7: ORD0006 | B7: West | C7: UK | D7: Clothing | E7: Online | F7: High | G7: 44932 | H7: 49 | I7: 308.07 | J7: 113.32 | K7: =IF(B7="",0,COUNTIF($B$2:$B$351,B7)) -> 106 | L7: =IF(D7="",0,COUNTIF($D$2:$D$351,D7)) -> 67 | M7: =IF(B7="",$Z$18,B7) -> West | N7: =IF(D7="",$Z$19,D7) -> Clothing | O7: =IF(H7="",$Y$24,H7) -> 49 | P7: =IF(I7="",$Z$24,I7) -> 308.07 | Q7: =H7*I7 -> 15095.43 | R7: =Q7-(H7*J7) -> 9542.75 | Y7: Order ID | Z7: =COUNTBLANK(A2:A351) -> 0
A8: ORD0007 | B8: North | C8: Germany | D8: Clothing | E8: Online | F8: Low | G8: 44933 | H8: 34 | I8: 244.78 | J8: 377.07 | K8: =IF(B8="",0,COUNTIF($B$2:$B$351,B8)) -> 78 | L8: =IF(D8="",0,COUNTIF($D$2:$D$351,D8)) -> 67 | M8: =IF(B8="",$Z$18,B8) -> North | N8: =IF(D8="",$Z$19,D8) -> Clothing | O8: =IF(H8="",$Y$24,H8) -> 34 | P8: =IF(I8="",$Z$24,I8) -> 244.78 | Q8: =H8*I8 -> 8322.52 | R8: =Q8-(H8*J8) -> -4497.86 | Y8: Region | Z8: =COUNTBLANK(B2:B351) -> 0
A9: ORD0008 | B9: North | C9: India | D9: Beverages | E9: Online | F9: High | G9: 44934 | H9: 270 | I9: 332.11 | J9: 349.59 | K9: =IF(B9="",0,COUNTIF($B$2:$B$351,B9)) -> 78 | L9: =IF(D9="",0,COUNTIF($D$2:$D$351,D9)) -> 83 | M9: =IF(B9="",$Z$18,B9) -> North | N9: =IF(D9="",$Z$19,D9) -> Beverages | O9: =IF(H9="",$Y$24,H9) -> 270 | P9: =IF(I9="",$Z$24,I9) -> 332.11 | Q9: =H9*I9 -> 89669.7 | R9: =Q9-(H9*J9) -> -4719.6 | Y9: Country | Z9: =COUNTBLANK(C2:C351) -> 0
A10: ORD0009 | B10: East | C10: India | D10: Beverages | E10: Online | F10: Low | G10: 44935 | H10: 404 | I10: 278.74 | J10: 66.38 | K10: =IF(B10="",0,COUNTIF($B$2:$B$351,B10)) -> 91 | L10: =IF(D10="",0,COUNTIF($D$2:$D$351,D10)) -> 83 | M10: =IF(B10="",$Z$18,B10) -> East | N10: =IF(D10="",$Z$19,D10) -> Beverages | O10: =IF(H10="",$Y$24,H10) -> 404 | P10: =IF(I10="",$Z$24,I10) -> 278.74 | Q10: =H10*I10 -> 112610.96 | R10: =Q10-(H10*J10) -> 85793.44 | Y10: Category | Z10: =COUNTBLANK(D2:D351) -> 0
A11: ORD0010 | B11: West | C11: USA | D11: Furniture | E11: Online | F11: Medium | G11: 44936 | H11: 452 | I11: 300.75 | J11: 314.94 | K11: =IF(B11="",0,COUNTIF($B$2:$B$351,B11)) -> 106 | L11: =IF(D11="",0,COUNTIF($D$2:$D$351,D11)) -> 69 | M11: =IF(B11="",$Z$18,B11) -> West | N11: =IF(D11="",$Z$19,D11) -> Furniture | O11: =IF(H11="",$Y$24,H11) -> 452 | P11: =IF(I11="",$Z$24,I11) -> 300.75 | Q11: =H11*I11 -> 135939 | R11: =Q11-(H11*J11) -> -6413.88 | Y11: Sales Channel | Z11: =COUNTBLANK(E2:E351) -> 0
A12: ORD0011 | B12: East | C12: USA | D12: Food | E12: Online | F12: Low | G12: 44937 | H12: 235 | I12: 393 | J12: 230.69 | K12: =IF(B12="",0,COUNTIF($B$2:$B$351,B12)) -> 91 | L12: =IF(D12="",0,COUNTIF($D$2:$D$351,D12)) -> 61 | M12: =IF(B12="",$Z$18,B12) -> East | N12: =IF(D12="",$Z$19,D12) -> Food | O12: =IF(H12="",$Y$24,H12) -> 235 | P12: =IF(I12="",$Z$24,I12) -> 393 | Q12: =H12*I12 -> 92355 | R12: =Q12-(H12*J12) -> 38142.85 | Y12: Order Priority | Z12: =COUNTBLANK(F2:F351) -> 0
A13: ORD0012 | B13: East | C13: UK | D13: Furniture | E13: Offline | F13: Medium | G13: 44938 | H13: 481 | I13: 243.05 | J13: 227.5 | K13: =IF(B13="",0,COUNTIF($B$2:$B$351,B13)) -> 91 | L13: =IF(D13="",0,COUNTIF($D$2:$D$351,D13)) -> 69 | M13: =IF(B13="",$Z$18,B13) -> East | N13: =IF(D13="",$Z$19,D13) -> Furniture | O13: =IF(H13="",$Y$24,H13) -> 481 | P13: =IF(I13="",$Z$24,I13) -> 243.05 | Q13: =H13*I13 -> 116907.05 | R13: =Q13-(H13*J13) -> 7479.55 | Y13: Order Date | Z13: =COUNTBLANK(G2:G351) -> 0
A14: ORD0013 | B14: East | C14: Germany | D14: Food | E14: Offline | F14: Low | G14: 44939 | H14: 133 | I14: 25.17 | J14: 157.64 | K14: =IF(B14="",0,COUNTIF($B$2:$B$351,B14)) -> 91 | L14: =IF(D14="",0,COUNTIF($D$2:$D$351,D14)) -> 61 | M14: =IF(B14="",$Z$18,B14) -> East | N14: =IF(D14="",$Z$19,D14) -> Food | O14: =IF(H14="",$Y$24,H14) -> 133 | P14: =IF(I14="",$Z$24,I14) -> 25.17 | Q14: =H14*I14 -> 3347.61 | R14: =Q14-(H14*J14) -> -17618.51 | Y14: Units Sold | Z14: =COUNTBLANK(H2:H351) -> 0
A15: ORD0014 | B15: East | C15: USA | D15: Food | E15: Offline | F15: Low | G15: 44940 | H15: 472 | I15: 86.18 | J15: 201.46 | K15: =IF(B15="",0,COUNTIF($B$2:$B$351,B15)) -> 91 | L15: =IF(D15="",0,COUNTIF($D$2:$D$351,D15)) -> 61 | M15: =IF(B15="",$Z$18,B15) -> East | N15: =IF(D15="",$Z$19,D15) -> Food | O15: =IF(H15="",$Y$24,H15) -> 472 | P15: =IF(I15="",$Z$24,I15) -> 86.18 | Q15: =H15*I15 -> 40676.96 | R15: =Q15-(H15*J15) -> -54412.16 | Y15: Unit Price | Z15: =COUNTBLANK(I2:I351) -> 0
A16: ORD0015 | B16: West | C16: India | D16: Beverages | E16: Offline | F16: Low | G16: 44941 | H16: 47 | I16: 222.11 | J16: 160.08 | K16: =IF(B16="",0,COUNTIF($B$2:$B$351,B16)) -> 106 | L16: =IF(D16="",0,COUNTIF($D$2:$D$351,D16)) -> 83 | M16: =IF(B16="",$Z$18,B16) -> West | N16: =IF(D16="",$Z$19,D16) -> Beverages | O16: =IF(H16="",$Y$24,H16) -> 47 | P16: =IF(I16="",$Z$24,I16) -> 222.11 | Q16: =H16*I16 -> 10439.17 | R16: =Q16-(H16*J16) -> 2915.41 | Y16: Unit Cost | Z16: =COUNTBLANK(J2:J351) -> 0
A17: ORD0016 | B17: North | C17: Germany | D17: Electronics | E17: Online | F17: High | G17: 44942 | H17: 337 | I17: 363.79 | J17: 216.81 | K17: =IF(B17="",0,COUNTIF($B$2:$B$351,B17)) -> 78 | L17: =IF(D17="",0,COUNTIF($D$2:$D$351,D17)) -> 70 | M17: =IF(B17="",$Z$18,B17) -> North | N17: =IF(D17="",$Z$19,D17) -> Electronics | O17: =IF(H17="",$Y$24,H17) -> 337 | P17: =IF(I17="",$Z$24,I17) -> 363.79 | Q17: =H17*I17 -> 122597.23 | R17: =Q17-(H17*J17) -> 49532.26
A18: ORD0017 | B18: West | C18: Germany | D18: Electronics | E18: Online | F18: High | G18: 44943 | H18: 260 | I18: 298.67 | J18: 251.92 | K18: =IF(B18="",0,COUNTIF($B$2:$B$351,B18)) -> 106 | L18: =IF(D18="",0,COUNTIF($D$2:$D$351,D18)) -> 70 | M18: =IF(B18="",$Z$18,B18) -> West | N18: =IF(D18="",$Z$19,D18) -> Electronics | O18: =IF(H18="",$Y$24,H18) -> 260 | P18: =IF(I18="",$Z$24,I18) -> 298.67 | Q18: =H18*I18 -> 77654.2 | R18: =Q18-(H18*J18) -> 12155 | Y18: Region Mode | Z18: =INDEX($B$2:$B$351,MATCH(MAX($K$2:$K$351),$K$2:$K$351,0)) -> West
A19: ORD0018 | B19: West | C19: India | D19: Clothing | E19: Offline | F19: Medium | G19: 44944 | H19: 398 | I19: 326.9 | J19: 270.37 | K19: =IF(B19="",0,COUNTIF($B$2:$B$351,B19)) -> 106 | L19: =IF(D19="",0,COUNTIF($D$2:$D$351,D19)) -> 67 | M19: =IF(B19="",$Z$18,B19) -> West | N19: =IF(D19="",$Z$19,D19) -> Clothing | O19: =IF(H19="",$Y$24,H19) -> 398 | P19: =IF(I19="",$Z$24,I19) -> 326.9 | Q19: =H19*I19 -> 130106.2 | R19: =Q19-(H19*J19) -> 22498.94 | Y19: Category Mode | Z19: =INDEX($D$2:$D$351,MATCH(MAX($L$2:$L$351),$L$2:$L$351,0)) -> Beverages
A20: ORD0019 | B20: West | C20: USA | D20: Beverages | E20: Online | F20: Medium | G20: 44945 | H20: 185 | I20: 242.24 | J20: 213.93 | K20: =IF(B20="",0,COUNTIF($B$2:$B$351,B20)) -> 106 | L20: =IF(D20="",0,COUNTIF($D$2:$D$351,D20)) -> 83 | M20: =IF(B20="",$Z$18,B20) -> West | N20: =IF(D20="",$Z$19,D20) -> Beverages | O20: =IF(H20="",$Y$24,H20) -> 185 | P20: =IF(I20="",$Z$24,I20) -> 242.24 | Q20: =H20*I20 -> 44814.4 | R20: =Q20-(H20*J20) -> 5237.35
A21: ORD0020 | B21: East | C21: India | D21: Food | E21: Offline | F21: High | G21: 44946 | H21: 99 | I21: 309.79 | J21: 289.13 | K21: =IF(B21="",0,COUNTIF($B$2:$B$351,B21)) -> 91 | L21: =IF(D21="",0,COUNTIF($D$2:$D$351,D21)) -> 61 | M21: =IF(B21="",$Z$18,B21) -> East | N21: =IF(D21="",$Z$19,D21) -> Food | O21: =IF(H21="",$Y$24,H21) -> 99 | P21: =IF(I21="",$Z$24,I21) -> 309.79 | Q21: =H21*I21 -> 30669.21 | R21: =Q21-(H21*J21) -> 2045.34
A22: ORD0021 | B22: South | C22: Germany | D22: Electronics | E22: Offline | F22: Medium | G22: 44947 | H22: 411 | I22: 167.86 | J22: 58.23 | K22: =IF(B22="",0,COUNTIF($B$2:$B$351,B22)) -> 75 | L22: =IF(D22="",0,COUNTIF($D$2:$D$351,D22)) -> 70 | M22: =IF(B22="",$Z$18,B22) -> South | N22: =IF(D22="",$Z$19,D22) -> Electronics | O22: =IF(H22="",$Y$24,H22) -> 411 | P22: =IF(I22="",$Z$24,I22) -> 167.86 | Q22: =H22*I22 -> 68990.46 | R22: =Q22-(H22*J22) -> 45057.93
A23: ORD0022 | B23: North | C23: Australia | D23: Food | E23: Offline | F23: High | G23: 44948 | H23: 463 | I23: 237.74 | J23: 86.37 | K23: =IF(B23="",0,COUNTIF($B$2:$B$351,B23)) -> 78 | L23: =IF(D23="",0,COUNTIF($D$2:$D$351,D23)) -> 61 | M23: =IF(B23="",$Z$18,B23) -> North | N23: =IF(D23="",$Z$19,D23) -> Food | O23: =IF(H23="",$Y$24,H23) -> 463 | P23: =IF(I23="",$Z$24,I23) -> 237.74 | Q23: =H23*I23 -> 110073.62 | R23: =Q23-(H23*J23) -> 70084.31 | Y23: Avg Units Sold | Z23: Avg Unit Price
A24: ORD0023 | B24: South | C24: Australia | D24: Electronics | E24: Online | F24: Low | G24: 44949 | H24: 46 | I24: 373.42 | J24: 327.86 | K24: =IF(B24="",0,COUNTIF($B$2:$B$351,B24)) -> 75 | L24: =IF(D24="",0,COUNTIF($D$2:$D$351,D24)) -> 70 | M24: =IF(B24="",$Z$18,B24) -> South | N24: =IF(D24="",$Z$19,D24) -> Electronics | O24: =IF(H24="",$Y$24,H24) -> 46 | P24: =IF(I24="",$Z$24,I24) -> 373.42 | Q24: =H24*I24 -> 17177.32 | R24: =Q24-(H24*J24) -> 2095.76 | Y24: =AVERAGE(H2:H351) -> 255.90294 | Z24: =AVERAGE(I2:I351) -> 249.64521
A25: ORD0024 | B25: West | C25: UK | D25: Electronics | E25: Offline | F25: Medium | G25: 44950 | H25: 325 | I25: 436.56 | J25: 130.37 | K25: =IF(B25="",0,COUNTIF($B$2:$B$351,B25)) -> 106 | L25: =IF(D25="",0,COUNTIF($D$2:$D$351,D25)) -> 70 | M25: =IF(B25="",$Z$18,B25) -> West | N25: =IF(D25="",$Z$19,D25) -> Electronics | O25: =IF(H25="",$Y$24,H25) -> 325 | P25: =IF(I25="",$Z$24,I25) -> 436.56 | Q25: =H25*I25 -> 141882 | R25: =Q25-(H25*J25) -> 99511.75
A26: ORD0025 | B26: West | C26: India | D26: Beverages | E26: Offline | F26: Medium | G26: 44951 | H26: 185 | I26: 219.66 | J26: 11.11 | K26: =IF(B26="",0,COUNTIF($B$2:$B$351,B26)) -> 106 | L26: =IF(D26="",0,COUNTIF($D$2:$D$351,D26)) -> 83 | M26: =IF(B26="",$Z$18,B26) -> West | N26: =IF(D26="",$Z$19,D26) -> Beverages | O26: =IF(H26="",$Y$24,H26) -> 185 | P26: =IF(I26="",$Z$24,I26) -> 219.66 | Q26: =H26*I26 -> 40637.1 | R26: =Q26-(H26*J26) -> 38581.75
A27: ORD0026 | B27: South | C27: India | D27: Beverages | E27: Offline | F27: High | G27: 44952 | H27: 470 | I27: 26.61 | J27: 63.21 | K27: =IF(B27="",0,COUNTIF($B$2:$B$351,B27)) -> 75 | L27: =IF(D27="",0,COUNTIF($D$2:$D$351,D27)) -> 83 | M27: =IF(B27="",$Z$18,B27) -> South | N27: =IF(D27="",$Z$19,D27) -> Beverages | O27: =IF(H27="",$Y$24,H27) -> 470 | P27: =IF(I27="",$Z$24,I27) -> 26.61 | Q27: =H27*I27 -> 12506.7 | R27: =Q27-(H27*J27) -> -17202
A28: ORD0027 | B28: South | C28: UK | D28: Furniture | E28: Online | F28: Medium | G28: 44953 | H28: 293 | I28: 85.03 | J28: 91 | K28: =IF(B28="",0,COUNTIF($B$2:$B$351,B28)) -> 75 | L28: =IF(D28="",0,COUNTIF($D$2:$D$351,D28)) -> 69 | M28: =IF(B28="",$Z$18,B28) -> South | N28: =IF(D28="",$Z$19,D28) -> Furniture | O28: =IF(H28="",$Y$24,H28) -> 293 | P28: =IF(I28="",$Z$24,I28) -> 85.03 | Q28: =H28*I28 -> 24913.79 | R28: =Q28-(H28*J28) -> -1749.21
A29: ORD0028 | B29: South | C29: UK | D29: Food | E29: Online | F29: Medium | G29: 44954 | H29: 462 | I29: 249.64521 | J29: 383.01 | K29: =IF(B29="",0,COUNTIF($B$2:$B$351,B29)) -> 75 | L29: =IF(D29="",0,COUNTIF($D$2:$D$351,D29)) -> 61 | M29: =IF(B29="",$Z$18,B29) -> South | N29: =IF(D29="",$Z$19,D29) -> Food | O29: =IF(H29="",$Y$24,H29) -> 462 | P29: =IF(I29="",$Z$24,I29) -> 249.64521 | Q29: =H29*I29 -> 115336.09 | R29: =Q29-(H29*J29) -> -61614.535
A30: ORD0029 | B30: West | C30: UK | D30: Beverages | E30: Offline | F30: Low | G30: 44955 | H30: 470 | I30: 328.37 | J30: 230.07 | K30: =IF(B30="",0,COUNTIF($B$2:$B$351,B30)) -> 106 | L30: =IF(D30="",0,COUNTIF($D$2:$D$351,D30)) -> 83 | M30: =IF(B30="",$Z$18,B30) -> West | N30: =IF(D30="",$Z$19,D30) -> Beverages | O30: =IF(H30="",$Y$24,H30) -> 470 | P30: =IF(I30="",$Z$24,I30) -> 328.37 | Q30: =H30*I30 -> 154333.9 | R30: =Q30-(H30*J30) -> 46201 | Y30: Total Price for ORD0123 | Z30: =INDEX($Q$2:$Q$351,MATCH("ORD0123",$A$2:$A$351,0)) -> 15849.3
A31: ORD0030 | B31: West | C31: Germany | D31: Beverages | E31: Online | F31: Medium | G31: 44956 | H31: 90 | I31: 169.5 | J31: 373.23 | K31: =IF(B31="",0,COUNTIF($B$2:$B$351,B31)) -> 106 | L31: =IF(D31="",0,COUNTIF($D$2:$D$351,D31)) -> 83 | M31: =IF(B31="",$Z$18,B31) -> West | N31: =IF(D31="",$Z$19,D31) -> Beverages | O31: =IF(H31="",$Y$24,H31) -> 90 | P31: =IF(I31="",$Z$24,I31) -> 169.5 | Q31: =H31*I31 -> 15255 | R31: =Q31-(H31*J31) -> -18335.7
A32: ORD0031 | B32: West | C32: India | D32: Beverages | E32: Online | F32: Low | G32: 44957 | H32: 123 | I32: 273.53 | J32: 230.92 | K32: =IF(B32="",0,COUNTIF($B$2:$B$351,B32)) -> 106 | L32: =IF(D32="",0,COUNTIF($D$2:$D$351,D32)) -> 83 | M32: =IF(B32="",$Z$18,B32) -> West | N32: =IF(D32="",$Z$19,D32) -> Beverages | O32: =IF(H32="",$Y$24,H32) -> 123 | P32: =IF(I32="",$Z$24,I32) -> 273.53 | Q32: =H32*I32 -> 33644.19 | R32: =Q32-(H32*J32) -> 5241.03
A33: ORD0032 | B33: North | C33: Germany | D33: Beverages | E33: Online | F33: High | G33: 44958 | H33: 49 | I33: 249.17 | J33: 192.78 | K33: =IF(B33="",0,COUNTIF($B$2:$B$351,B33)) -> 78 | L33: =IF(D33="",0,COUNTIF($D$2:$D$351,D33)) -> 83 | M33: =IF(B33="",$Z$18,B33) -> North | N33: =IF(D33="",$Z$19,D33) -> Beverages | O33: =IF(H33="",$Y$24,H33) -> 49 | P33: =IF(I33="",$Z$24,I33) -> 249.17 | Q33: =H33*I33 -> 12209.33 | R33: =Q33-(H33*J33) -> 2763.11
A34: ORD0033 | B34: West | C34: UK | D34: Beverages | E34: Online | F34: Medium | G34: 44959 | H34: 310 | I34: 45.36 | J34: 126.86 | K34: =IF(B34="",0,COUNTIF($B$2:$B$351,B34)) -> 106 | L34: =IF(D34="",0,COUNTIF($D$2:$D$351,D34)) -> 83 | M34: =IF(B34="",$Z$18,B34) -> West | N34: =IF(D34="",$Z$19,D34) -> Beverages | O34: =IF(H34="",$Y$24,H34) -> 310 | P34: =IF(I34="",$Z$24,I34) -> 45.36 | Q34: =H34*I34 -> 14061.6 | R34: =Q34-(H34*J34) -> -25265
A35: ORD0034 | B35: South | C35: India | D35: Clothing | E35: Online | F35: Low | G35: 44960 | H35: 233 | I35: 204.61 | J35: 243.34 | K35: =IF(B35="",0,COUNTIF($B$2:$B$351,B35)) -> 75 | L35: =IF(D35="",0,COUNTIF($D$2:$D$351,D35)) -> 67 | M35: =IF(B35="",$Z$18,B35) -> South | N35: =IF(D35="",$Z$19,D35) -> Clothing | O35: =IF(H35="",$Y$24,H35) -> 233 | P35: =IF(I35="",$Z$24,I35) -> 204.61 | Q35: =H35*I35 -> 47674.13 | R35: =Q35-(H35*J35) -> -9024.09
A36: ORD0035 | B36: South | C36: Germany | D36: Food | E36: Online | F36: High | G36: 44961 | H36: 327 | I36: 114.18 | J36: 57.4 | K36: =IF(B36="",0,COUNTIF($B$2:$B$351,B36)) -> 75 | L36: =IF(D36="",0,COUNTIF($D$2:$D$351,D36)) -> 61 | M36: =IF(B36="",$Z$18,B36) -> South | N36: =IF(D36="",$Z$19,D36) -> Food | O36: =IF(H36="",$Y$24,H36) -> 327 | P36: =IF(I36="",$Z$24,I36) -> 114.18 | Q36: =H36*I36 -> 37336.86 | R36: =Q36-(H36*J36) -> 18567.06
A37: ORD0036 | B37: North | C37: Germany | D37: Beverages | E37: Online | F37: Medium | G37: 44962 | H37: 358 | I37: 212.11 | J37: 359.51 | K37: =IF(B37="",0,COUNTIF($B$2:$B$351,B37)) -> 78 | L37: =IF(D37="",0,COUNTIF($D$2:$D$351,D37)) -> 83 | M37: =IF(B37="",$Z$18,B37) -> North | N37: =IF(D37="",$Z$19,D37) -> Beverages | O37: =IF(H37="",$Y$24,H37) -> 358 | P37: =IF(I37="",$Z$24,I37) -> 212.11 | Q37: =H37*I37 -> 75935.38 | R37: =Q37-(H37*J37) -> -52769.2
A38: ORD0037 | B38: West | C38: UK | D38: Food | E38: Online | F38: High | G38: 44963 | H38: 124 | I38: 249.64521 | J38: 332.07 | K38: =IF(B38="",0,COUNTIF($B$2:$B$351,B38)) -> 106 | L38: =IF(D38="",0,COUNTIF($D$2:$D$351,D38)) -> 61 | M38: =IF(B38="",$Z$18,B38) -> West | N38: =IF(D38="",$Z$19,D38) -> Food | O38: =IF(H38="",$Y$24,H38) -> 124 | P38: =IF(I38="",$Z$24,I38) -> 249.64521 | Q38: =H38*I38 -> 30956.006 | R38: =Q38-(H38*J38) -> -10220.674
A39: ORD0038 | B39: North | C39: India | D39: Clothing | E39: Online | F39: Medium | G39: 44964 | H39: 195 | I39: 421.02 | J39: 128.38 | K39: =IF(B39="",0,COUNTIF($B$2:$B$351,B39)) -> 78 | L39: =IF(D39="",0,COUNTIF($D$2:$D$351,D39)) -> 67 | M39: =IF(B39="",$Z$18,B39) -> North | N39: =IF(D39="",$Z$19,D39) -> Clothing | O39: =IF(H39="",$Y$24,H39) -> 195 | P39: =IF(I39="",$Z$24,I39) -> 421.02 | Q39: =H39*I39 -> 82098.9 | R39: =Q39-(H39*J39) -> 57064.8
A40: ORD0039 | B40: North | C40: UK | D40: Clothing | E40: Online | F40: High | G40: 44965 | H40: 255.90294 | I40: 91.23 | J40: 381.21 | K40: =IF(B40="",0,COUNTIF($B$2:$B$351,B40)) -> 78 | L40: =IF(D40="",0,COUNTIF($D$2:$D$351,D40)) -> 67 | M40: =IF(B40="",$Z$18,B40) -> North | N40: =IF(D40="",$Z$19,D40) -> Clothing | O40: =IF(H40="",$Y$24,H40) -> 255.90294 | P40: =IF(I40="",$Z$24,I40) -> 91.23 | Q40: =H40*I40 -> 23346.025 | R40: =Q40-(H40*J40) -> -74206.735
...
